<?xml version="1.0" ?>


<robot
  name="xm_robot">
  <link
    name="base_link">
    <inertial>
      <origin
        xyz="-0.030096 -0.00033289 0.43437"
        rpy="0 0 0" />
      <mass
        value="28.429" />
      <inertia
        ixx="3.3043"
        ixy="0.00011321"
        ixz="-0.22301"
        iyy="3.3216"
        iyz="0.0036429"
        izz="0.40235" />
    </inertial>
    <visual>
      <origin
        xyz="0 0 0"
        rpy="0 0 0" />
      <geometry>
        <mesh
          filename="package://xm_description/meshes/base_link.STL" />
      </geometry>
      <material
        name="">
        <color
          rgba="1 1 1 1" />
      </material>
    </visual>
    <collision>
      <origin
        xyz="0 0 0"
        rpy="0 0 0" />
      <geometry>
        <mesh
          filename="package://xm_description/meshes/base_link_l.stl" />
      </geometry>
    </collision>
  </link>
  <link
    name="link_wheel_1">
    <inertial>
      <origin
        xyz="8.0491E-16 -1.3878E-17 -0.0042221"
        rpy="0 0 0" />
      <mass
        value="0.34065" />
      <inertia
        ixx="0.00030696"
        ixy="-3.4634E-22"
        ixz="-7.3136E-19"
        iyy="0.00030696"
        iyz="8.9342E-21"
        izz="0.00029643" />
    </inertial>
    <visual>
      <origin
        xyz="0 0 0"
        rpy="0 0 0" />
      <geometry>
        <mesh
          filename="package://xm_description/meshes/link_wheel_1.STL" />
      </geometry>
      <material
        name="">
        <color
          rgba="1 1 1 1" />
      </material>
    </visual>
    <collision>
      <origin
        xyz="0 0 0"
        rpy="0 0 0" />
      <geometry>
        <mesh
          filename="package://xm_description/meshes/link_wheel_1_l.stl" />
      </geometry>
    </collision>
  </link>
  <joint
    name="joint_wheel_1"
    type="continuous">
    <origin
      xyz="0.19419 0.00022708 -0.042"
      rpy="-1.5708 0 -1.5708" />
    <parent
      link="base_link" />
    <child
      link="link_wheel_1" />
    <axis
      xyz="0 0 1" />
  </joint>
  <link
    name="link_wheel_2">
    <inertial>
      <origin
        xyz="-1.3878E-17 1.3878E-17 -0.0042221"
        rpy="0 0 0" />
      <mass
        value="0.34065" />
      <inertia
        ixx="0.00030696"
        ixy="1.0391E-20"
        ixz="1.3553E-20"
        iyy="0.00030696"
        iyz="4.616E-21"
        izz="0.00029643" />
    </inertial>
    <visual>
      <origin
        xyz="0 0 0"
        rpy="0 0 0" />
      <geometry>
        <mesh
          filename="package://xm_description/meshes/link_wheel_2.STL" />
      </geometry>
      <material
        name="">
        <color
          rgba="0.64706 0.61961 0.58824 1" />
      </material>
    </visual>
    <collision>
      <origin
        xyz="0 0 0"
        rpy="0 0 0" />
      <geometry>
        <mesh
          filename="package://xm_description/meshes/link_wheel_2_l.stl" />
      </geometry>
    </collision>
  </link>
  <joint
    name="joint_wheel_2"
    type="continuous">
    <origin
      xyz="-0.096968 -0.16833 -0.042"
      rpy="-1.5708 0 2.618" />
    <parent
      link="base_link" />
    <child
      link="link_wheel_2" />
    <axis
      xyz="0 0 1" />
  </joint>
  <link
    name="link_wheel_3">
    <inertial>
      <origin
        xyz="1.4572E-15 0 -0.0042221"
        rpy="0 0 0" />
      <mass
        value="0.34065" />
      <inertia
        ixx="0.00030696"
        ixy="-3.3256E-21"
        ixz="2.7105E-20"
        iyy="0.00030696"
        iyz="-1.1933E-20"
        izz="0.00029643" />
    </inertial>
    <visual>
      <origin
        xyz="0 0 0"
        rpy="0 0 0" />
      <geometry>
        <mesh
          filename="package://xm_description/meshes/link_wheel_3.STL" />
      </geometry>
      <material
        name="">
        <color
          rgba="0.64706 0.61961 0.58824 1" />
      </material>
    </visual>
    <collision>
      <origin
        xyz="0 0 0"
        rpy="0 0 0" />
      <geometry>
        <mesh
          filename="package://xm_description/meshes/link_wheel_3_l.stl" />
      </geometry>
    </collision>
  </link>
  <joint
    name="joint_wheel_3"
    type="continuous">
    <origin
      xyz="-0.097362 0.1681 -0.042"
      rpy="-1.5708 0 0.5236" />
    <parent
      link="base_link" />
    <child
      link="link_wheel_3" />
    <axis
      xyz="0 0 1" />
  </joint>
  <link
    name="link_laser">
    <inertial>
      <origin
        xyz="0 -3.8367E-05 -0.0055273"
        rpy="0 0 0" />
      <mass
        value="0.1221" />
      <inertia
        ixx="6.4774E-05"
        ixy="-4.322E-13"
        ixz="7.0123E-21"
        iyy="6.4681E-05"
        iyz="-1.0865E-07"
        izz="3.7788E-05" />
    </inertial>
    <visual>
      <origin
        xyz="0 0 0"
        rpy="0 0 0" />
      <geometry>
        <mesh
          filename="package://xm_description/meshes/link_laser.STL" />
      </geometry>
      <material
        name="">
        <color
          rgba="0.25098 0.25098 0.25098 1" />
      </material>
    </visual>
    <collision>
      <origin
        xyz="0 0 0"
        rpy="0 0 0" />
      <geometry>
        <mesh
          filename="package://xm_description/meshes/link_laser_l.stl" />
      </geometry>
    </collision>
  </link>
  <joint
    name="joint_laser"
    type="fixed">
    <origin
      xyz="0.20674 0.00022708 0.181"
      rpy="-6.7054E-18 6.9389E-17 -1.5708" />
    <parent
      link="base_link" />
    <child
      link="link_laser" />
    <axis
      xyz="0 0 0" />
  </joint>
  <link
    name="link_lift">
    <inertial>
      <origin
        xyz="-8.3267E-17 0.048515 0.0020048"
        rpy="0 0 0" />
      <mass
        value="1.7076" />
      <inertia
        ixx="0.015015"
        ixy="2.1531E-18"
        ixz="-3.952E-19"
        iyy="0.015774"
        iyz="-8.1536E-05"
        izz="0.0028516" />
    </inertial>
    <visual>
      <origin
        xyz="0 0 0"
        rpy="0 0 0" />
      <geometry>
        <mesh
          filename="package://xm_description/meshes/link_lift.STL" />
      </geometry>
      <material
        name="">
        <color
          rgba="0.89804 0.91765 0.92941 1" />
      </material>
    </visual>
    <collision>
      <origin
        xyz="0 0 0"
        rpy="0 0 0" />
      <geometry>
        <mesh
          filename="package://xm_description/meshes/link_lift_l.stl" />
      </geometry>
    </collision>
  </link>
  <joint
    name="joint_lift"
    type="prismatic">
    <origin
      xyz="-0.04456 0.00022708 0.72985"
      rpy="-2.7756E-17 0 -1.5708" />
    <parent
      link="base_link" />
    <child
      link="link_lift" />
    <axis
      xyz="0 0 -1" />
    <limit
      lower="-0.15"
      upper="0.15"
      effort="500"
      velocity="1" />
  </joint>
  <link
    name="link_waist">
    <inertial>
      <origin
        xyz="0.00035629 0.050223 0.014835"
        rpy="0 0 0" />
      <mass
        value="2.2632" />
      <inertia
        ixx="0.014881"
        ixy="2.8517E-05"
        ixz="-0.00013888"
        iyy="0.015217"
        iyz="0.00052947"
        izz="0.0095668" />
    </inertial>
    <visual>
      <origin
        xyz="0 0 0"
        rpy="0 0 0" />
      <geometry>
        <mesh
          filename="package://xm_description/meshes/link_waist.STL" />
      </geometry>
      <material
        name="">
        <color
          rgba="0.89804 0.91765 0.92941 1" />
      </material>
    </visual>
    <collision>
      <origin
        xyz="0 0 0"
        rpy="0 0 0" />
      <geometry>
        <mesh
          filename="package://xm_description/meshes/link_waist_l.stl" />
      </geometry>
    </collision>
  </link>
  <joint
    name="joint_waist"
    type="revolute">
    <origin
      xyz="0 0.0945 0.00415"
      rpy="2.7756E-17 1.3056E-31 -2.8372E-16" />
    <parent
      link="link_lift" />
    <child
      link="link_waist" />
    <axis
      xyz="0 0 1" />
    <limit
	  lower="-1.047"
      upper="1.047"
      effort="500"
      velocity="1" />
  </joint>
  <link
    name="link_big_arm">
    <inertial>
      <origin
        xyz="0.095008 0.006168 0.0026321"
        rpy="0 0 0" />
      <mass
        value="1.2241" />
      <inertia
        ixx="0.0030013"
        ixy="0.00024375"
        ixz="0.0004659"
        iyy="0.017469"
        iyz="-1.9873E-05"
        izz="0.015447" />
    </inertial>
    <visual>
      <origin
        xyz="0 0 0"
        rpy="0 0 0" />
      <geometry>
        <mesh
          filename="package://xm_description/meshes/link_big_arm.STL" />
      </geometry>
      <material
        name="">
        <color
          rgba="0.89804 0.91765 0.92941 1" />
      </material>
    </visual>
    <collision>
      <origin
        xyz="0 0 0"
        rpy="0 0 0" />
      <geometry>
        <mesh
          filename="package://xm_description/meshes/link_big_arm_l.stl" />
      </geometry>
    </collision>
  </link>
  <joint
    name="joint_big_arm"
    type="revolute">
    <origin
      xyz="0 0.15678 -0.018"
      rpy="1.5708 -7.7037E-34 1.5708" />
    <parent
      link="link_waist" />
    <child
      link="link_big_arm" />
    <axis
      xyz="0 0 1" />
    <limit
      lower="-1.920"
	  upper="1.396"
      effort="500"
      velocity="1" />
  </joint>
  <link
    name="link_forearm">
    <inertial>
      <origin
        xyz="0.099759 -2.2204E-16 0.00013669"
        rpy="0 0 0" />
      <mass
        value="0.70102" />
      <inertia
        ixx="0.00073291"
        ixy="5.0551E-18"
        ixz="4.274E-05"
        iyy="0.0069521"
        iyz="7.8112E-19"
        izz="0.0066437" />
    </inertial>
    <visual>
      <origin
        xyz="0 0 0"
        rpy="0 0 0" />
      <geometry>
        <mesh
          filename="package://xm_description/meshes/link_forearm.STL" />
      </geometry>
      <material
        name="">
        <color
          rgba="0.89804 0.91765 0.92941 1" />
      </material>
    </visual>
    <collision>
      <origin
        xyz="0 0 0"
        rpy="0 0 0" />
      <geometry>
        <mesh
          filename="package://xm_description/meshes/link_forearm_l.stl" />
      </geometry>
    </collision>
  </link>
  <joint
    name="joint_forearm"
    type="revolute">
    <origin
      xyz="0.35 0 0"
      rpy="-6.4095E-31 2.2204E-16 -7.7037E-34" />
    <parent
      link="link_big_arm" />
    <child
      link="link_forearm" />
    <axis
      xyz="0 0 -1" />
    <limit
      lower="-2.234"
      upper="2.234"
      effort="500"
      velocity="1" />
  </joint>
  <link
    name="link_wrist_pitching">
    <inertial>
      <origin
        xyz="1.7127E-09 -0.00034153 -1.195E-06"
        rpy="0 0 0" />
      <mass
        value="0.037514" />
      <inertia
        ixx="1.063E-05"
        ixy="1.0698E-13"
        ixz="-4.4237E-13"
        iyy="1.0507E-05"
        iyz="-1.5531E-11"
        izz="3.2674E-06" />
    </inertial>
    <visual>
      <origin
        xyz="0 0 0"
        rpy="0 0 0" />
      <geometry>
        <mesh
          filename="package://xm_description/meshes/link_wrist_pitching.STL" />
      </geometry>
      <material
        name="">
        <color
          rgba="0.89804 0.91765 0.92941 1" />
      </material>
    </visual>
    <collision>
      <origin
        xyz="0 0 0"
        rpy="0 0 0" />
      <geometry>
        <mesh
          filename="package://xm_description/meshes/link_wrist_pitching_l.stl" />
      </geometry>
    </collision>
  </link>
  <joint
    name="joint_wrist_pitching"
    type="revolute">
    <origin
      xyz="0.3 0 0"
      rpy="0 0 1.5708" />
    <parent
      link="link_forearm" />
    <child
      link="link_wrist_pitching" />
    <axis
      xyz="0 0 -1" />
    <limit
      lower="-2.182"
      upper="2.182"
      effort="500"
      velocity="1" />
  </joint>
  <link
    name="link_wrist_rotation">
    <inertial>
      <origin
        xyz="0.00041743 -0.00042922 0.069037"
        rpy="0 0 0" />
      <mass
        value="0.12901" />
      <inertia
        ixx="0.00010496"
        ixy="-2.1936E-07"
        ixz="5.5636E-07"
        iyy="0.00011251"
        iyz="-1.2571E-06"
        izz="3.1759E-05" />
    </inertial>
    <visual>
      <origin
        xyz="0 0 0"
        rpy="0 0 0" />
      <geometry>
        <mesh
          filename="package://xm_description/meshes/link_wrist_rotation.STL" />
      </geometry>
      <material
        name="">
        <color
          rgba="1 1 1 1" />
      </material>
    </visual>
    <collision>
      <origin
        xyz="0 0 0"
        rpy="0 0 0" />
      <geometry>
        <mesh
          filename="package://xm_description/meshes/link_wrist_rotation_l.stl" />
      </geometry>
    </collision>
  </link>
  <joint
    name="joint_wrist_rotation"
    type="continuous">
    <origin
      xyz="0 0 0"
      rpy="1.5708 -1.5708 0" />
    <parent
      link="link_wrist_pitching" />
    <child
      link="link_wrist_rotation" />
    <axis
      xyz="0 0 1" />
    <limit
      effort="500"
      velocity="1" />
  </joint>
  <link
    name="link_finger_right">
    <inertial>
      <origin
        xyz="0.067181 -0.0073582 2.014E-08"
        rpy="0 0 0" />
      <mass
        value="0.054127" />
      <inertia
        ixx="1.3972E-05"
        ixy="3.6354E-06"
        ixz="1.1594E-10"
        iyy="5.1741E-05"
        iyz="-1.601E-12"
        izz="4.3944E-05" />
    </inertial>
    <visual>
      <origin
        xyz="0 0 0"
        rpy="0 0 0" />
      <geometry>
        <mesh
          filename="package://xm_description/meshes/link_finger_right.STL" />
      </geometry>
      <material
        name="">
        <color
          rgba="1 1 1 0.875" />
      </material>
    </visual>
    <collision>
      <origin
        xyz="0 0 0"
        rpy="0 0 0" />
      <geometry>
        <mesh
          filename="package://xm_description/meshes/link_finger_right_l.stl" />
      </geometry>
    </collision>
  </link>
  <joint
    name="joint_finger_right"
    type="revolute">
    <origin
      xyz="0.01295 -0.00014458 0.091042"
      rpy="1.5708 -1.5708 0" />
    <parent
      link="link_wrist_rotation" />
    <child
      link="link_finger_right" />
    <axis
      xyz="0 0 -1" />
    <limit
      lower="0"
      upper="1.571"
      effort="500"
      velocity="1" />
  </joint>
  <link
    name="link_finger_left">
    <inertial>
      <origin
        xyz="0.067181 0.0073582 -2.014E-08"
        rpy="0 0 0" />
      <mass
        value="0.054127" />
      <inertia
        ixx="1.3972E-05"
        ixy="-3.6354E-06"
        ixz="-1.1594E-10"
        iyy="5.1741E-05"
        iyz="-1.601E-12"
        izz="4.3944E-05" />
    </inertial>
    <visual>
      <origin
        xyz="0 0 0"
        rpy="0 0 0" />
      <geometry>
        <mesh
          filename="package://xm_description/meshes/link_finger_left.STL" />
      </geometry>
      <material
        name="">
        <color
          rgba="1 1 1 0.875" />
      </material>
    </visual>
    <collision>
      <origin
        xyz="0 0 0"
        rpy="0 0 0" />
      <geometry>
        <mesh
          filename="package://xm_description/meshes/link_finger_left_l.stl" />
      </geometry>
    </collision>
  </link>
  <joint
    name="joint_finger_left"
    type="revolute">
    <origin
      xyz="-0.01295 -0.00014458 0.091042"
      rpy="1.5708 -1.5708 0" />
    <parent
      link="link_wrist_rotation" />
    <child
      link="link_finger_left" />
    <axis
      xyz="0 0 -1" />
    <limit
      lower="-1.571"
      upper="0"
      effort="500"
      velocity="1" 
	/>
    <!-- limit
	  lower="0"
	  upper="0"
	  effort="500"
	  velocity="1"
	/-->
  </joint>
  <link
    name="link_kinect">
    <inertial>
      <origin
        xyz="0.00024993 -0.00050157 -3.2753E-09"
        rpy="0 0 0" />
      <mass
        value="1.3398" />
      <inertia
        ixx="0.007821"
        ixy="-3.6481E-06"
        ixz="1.9233E-11"
        iyy="0.0080704"
        iyz="7.704E-11"
        izz="0.00058859" />
    </inertial>
    <visual>
      <origin
        xyz="0 0 0"
        rpy="0 0 0" />
      <geometry>
        <mesh
          filename="package://xm_description/meshes/link_kinect.STL" />
      </geometry>
      <material
        name="">
        <color
          rgba="0.49412 0.47059 0.47059 1" />
      </material>
    </visual>
    <collision>
      <origin
        xyz="0 0 0"
        rpy="0 0 0" />
      <geometry>
        <mesh
          filename="package://xm_description/meshes/link_kinect_l.stl" />
      </geometry>
    </collision>
  </link>
  <joint
    name="joint_kinect"
    type="revolute">
    <origin
      xyz="-0.06656 0.00022708 1.1145"
      rpy="1.5708 0 -6.1679E-17" />
    <parent
      link="base_link" />
    <child
      link="link_kinect" />
    <axis
      xyz="0 0 1" />
    <limit
      lower="-0.523"
      upper="0.523"
      effort="500"
      velocity="1" />
  </joint>
  <link
    name="link_camera">
    <inertial>
      <origin
        xyz="0.02355 0.0084844 -3.0636E-05"
        rpy="0 0 0" />
      <mass
        value="0.094765" />
      <inertia
        ixx="5.1998E-05"
        ixy="1.2567E-05"
        ixz="1.377E-07"
        iyy="7.5857E-05"
        iyz="2.5368E-08"
        izz="5.2142E-05" />
    </inertial>
    <visual>
      <origin
        xyz="0 0 0"
        rpy="0 0 0" />
      <geometry>
        <mesh
          filename="package://xm_description/meshes/link_camera.STL" />
      </geometry>
      <material
        name="">
        <color
          rgba="1 1 1 1" />
      </material>
    </visual>
    <collision>
      <origin
        xyz="0 0 0"
        rpy="0 0 0" />
      <geometry>
        <mesh
          filename="package://xm_description/meshes/link_camera_l.stl" />
      </geometry>
    </collision>
  </link>
  <joint
    name="joint_camera"
    type="fixed">
    <origin
      xyz="-0.001 0.032 0"
      rpy="5.7785E-17 0 0" />
    <parent
      link="link_kinect" />
    <child
      link="link_camera" />
    <axis
      xyz="0 0 0" />
  </joint>

 <transmission name="tran1">
	<type>transmission_interface/SimpleTransmission</type>
	<joint name="joint_wheel_1">
		<hardwareInterface>VelocityJointInterface</hardwareInterface>
	</joint>
	<actuator name="base_motor1">
		<hardwareInterface>VelocityJointInterface</hardwareInterface>
		<mechanicalReduction>1</mechanicalReduction>
	</actuator>
</transmission>

<transmission name="tran2">
	<type>transmission_interface/SimpleTransmission</type>
	<joint name="joint_wheel_2">
		<hardwareInterface>VelocityJointInterface</hardwareInterface>
	</joint>
	<actuator name="base_motor2">
		<hardwareInterface>VelocityJointInterface</hardwareInterface>
		<mechanicalReduction>1</mechanicalReduction>
	</actuator>
</transmission>

<transmission name="tran3">
	<type>transmission_interface/SimpleTransmission</type>
	<joint name="joint_wheel_3">
		<hardwareInterface>VelocityJointInterface</hardwareInterface>
	</joint>
	<actuator name="base_motor3">
		<hardwareInterface>VelocityJointInterface</hardwareInterface>
		<mechanicalReduction>1</mechanicalReduction>
	</actuator>
</transmission>

<transmission name="tran4">
	<type>transmission_interface/SimpleTransmission</type>
	<joint name="joint_kinect">
		<hardwareInterface>EffortJointInterface</hardwareInterface>
	</joint>
	<actuator name="kinect_servo">
		<hardwareInterface>EffortJointInterface</hardwareInterface>
		<mechanicalReduction>1</mechanicalReduction>
	</actuator>
</transmission>

<transmission name="tran5">
	<type>transmission_interface/SimpleTransmission</type>
	<joint name="joint_lift">
		<hardwareInterface>EffortJointInterface</hardwareInterface>
	</joint>
	<actuator name="lift_motor">
		<hardwareInterface>EffortJointInterface</hardwareInterface>
		<mechanicalReduction>1</mechanicalReduction>
	</actuator>
</transmission>

<transmission name="tran6">
	<type>transmission_interface/SimpleTransmission</type>
	<joint name="joint_waist">
		<hardwareInterface>EffortJointInterface</hardwareInterface>
	</joint>
	<actuator name="waist_motor">
		<hardwareInterface>EffortJointInterface</hardwareInterface>
		<mechanicalReduction>1</mechanicalReduction>
	</actuator>
</transmission>

<transmission name="tran7">
	<type>transmission_interface/SimpleTransmission</type>
	<joint name="joint_big_arm">
		<hardwareInterface>EffortJointInterface</hardwareInterface>
	</joint>
	<actuator name="big_arm_motor">
		<hardwareInterface>EffortJointInterface</hardwareInterface>
		<mechanicalReduction>1</mechanicalReduction>
	</actuator>
</transmission>

<transmission name="tran8">
	<type>transmission_interface/SimpleTransmission</type>
	<joint name="joint_forearm">
		<hardwareInterface>EffortJointInterface</hardwareInterface>
	</joint>
	<actuator name="forearm_motor">
		<hardwareInterface>EffortJointInterface</hardwareInterface>
		<mechanicalReduction>1</mechanicalReduction>
	</actuator>
</transmission>

<transmission name="tran9">
	<type>transmission_interface/SimpleTransmission</type>
	<joint name="joint_wrist_pitching">
		<hardwareInterface>EffortJointInterface</hardwareInterface>
	</joint>
	<actuator name="wrist_motor1">
		<hardwareInterface>EffortJointInterface</hardwareInterface>
		<mechanicalReduction>1</mechanicalReduction>
	</actuator>
</transmission>

<transmission name="tran10">
	<type>transmission_interface/SimpleTransmission</type>
	<joint name="joint_wrist_rotation">
		<hardwareInterface>EffortJointInterface</hardwareInterface>
	</joint>
	<actuator name="wrist_motor2">
		<hardwareInterface>EffortJointInterface</hardwareInterface>
		<mechanicalReduction>1</mechanicalReduction>
	</actuator>
</transmission>

<transmission name="tran11">
	<type>transmission_interface/SimpleTransmission</type>
	<joint name="joint_finger_left">
		<hardwareInterface>EffortJointInterface</hardwareInterface>
	</joint>
	<actuator name="finger">
		<hardwareInterface>EffortJointInterface</hardwareInterface>
		<mechanicalReduction>1</mechanicalReduction>
	</actuator>
</transmission>

<transmission name="tran12">
	<type>transmission_interface/SimpleTransmission</type>
	<joint name="joint_finger_right">
		<hardwareInterface>EffortJointInterface</hardwareInterface>
	</joint>
	<actuator name="finger">
		<hardwareInterface>EffortJointInterface</hardwareInterface>
		<mechanicalReduction>1</mechanicalReduction>
	</actuator>
</transmission>
</robot>
