<?xml version="1.0" ?>
<!-- =================================================================================== -->
<!-- |    This document was autogenerated by xacro from xm_robot_with_arm.xacro        | -->
<!-- |    EDITING THIS FILE BY HAND IS NOT RECOMMENDED                                 | -->
<!-- =================================================================================== -->
<robot name="xm_robot" xmlns:xacro="http://ros.org/wiki/xacro">
  <!-- The following xacro:include files set up definitions of parts of the robot body -->
  <material name="Black">
    <color rgba="0.2 0.2 0.2 1.0"/>
  </material>
  <material name="TransparentBlack">
    <color rgba="0.2 0.2 0.2 0.8"/>
  </material>
  <material name="Orange">
    <color rgba="1.0  0.55 0.0 1.0"/>
  </material>
  <material name="Grey">
    <color rgba="0.7 0.7 0.7 1.0"/>
  </material>
  <material name="DarkGrey">
    <color rgba="0.3 0.3 0.3 1.0"/>
  </material>
  <material name="Red">
    <color rgba="0.8 0.0 0.0 1.0"/>
  </material>
  <material name="White">
    <color rgba="1.0 1.0 1.0 1.0"/>
  </material>
  <material name="OffWhite">
    <color rgba="0.8 0.8 0.8 1.0"/>
  </material>
  <material name="Blue">
    <color rgba="0.0 0.0 0.8 1.0"/>
  </material>
  <material name="Green">
    <color rgba="0.0 0.8 0.0 1.0"/>
  </material>
  <material name="TransparentGreen">
    <color rgba="0.0 0.8 0.0 0.5"/>
  </material>
  <link name="base_footprint">
    <visual>
      <origin rpy="0 0 0" xyz="0 0 0"/>
      <geometry>
        <box size="0.05 0.05 0.001"/>
      </geometry>
      <material name="TransparentGreen"/>
    </visual>
  </link>
  <joint name="base_joint" type="fixed">
    <origin rpy="0 0 0" xyz="0 0 0"/>
    <parent link="base_footprint"/>
    <child link="base_link"/>
  </joint>
  <!-- Attach the base -->
  <link name="base_link">
    <visual>
      <origin rpy="0 0 0" xyz="0 0 0"/>
      <geometry>
        <mesh filename="package://xm_description/meshes/base_link.STL"/>
      </geometry>
      <material name="DarkGrey"/>
    </visual>
    <collision>
      <origin rpy="0 0 0" xyz="0 0 0"/>
      <geometry>
        <mesh filename="package://xm_description/meshes/base_link.stl"/>
      </geometry>
    </collision>
  </link>
  <!-- Add the drive wheels -->
  <joint name="joint_wheel_1" type="fixed">
    <origin rpy="-1.5708 0 -1.5708" xyz="0.19419 0.00022708 -0.042"/>
    <parent link="base_link"/>
    <child link="link_wheel_1"/>
    <axis xyz="0 0 1"/>
  </joint>
  <link name="link_wheel_1">
    <visual>
      <origin rpy="0 0 0" xyz="0 0 0"/>
      <geometry>
        <mesh filename="package://xm_description/meshes/link_wheel_1.STL"/>
      </geometry>
      <material name="Blue"/>
    </visual>
    <collision>
      <origin rpy="0 0 0" xyz="0 0 0"/>
      <geometry>
        <mesh filename="package://xm_description/meshes/link_wheel_1.stl"/>
      </geometry>
    </collision>
  </link>
  <joint name="joint_wheel_2" type="fixed">
    <origin rpy="-1.5708 0 2.618" xyz="-0.096968 -0.16833 -0.042"/>
    <parent link="base_link"/>
    <child link="link_wheel_2"/>
    <axis xyz="0 0 1"/>
  </joint>
  <link name="link_wheel_2">
    <visual>
      <origin rpy="0 0 0" xyz="0 0 0"/>
      <geometry>
        <mesh filename="package://xm_description/meshes/link_wheel_2.STL"/>
      </geometry>
      <material name="Blue"/>
    </visual>
    <collision>
      <origin rpy="0 0 0" xyz="0 0 0"/>
      <geometry>
        <mesh filename="package://xm_description/meshes/link_wheel_2.stl"/>
      </geometry>
    </collision>
  </link>
  <joint name="joint_wheel_3" type="fixed">
    <origin rpy="-1.5708 0 0.5236" xyz="-0.097362 0.1681 -0.042"/>
    <parent link="base_link"/>
    <child link="link_wheel_3"/>
    <axis xyz="0 0 1"/>
  </joint>
  <link name="link_wheel_3">
    <visual>
      <origin rpy="0 0 0" xyz="0 0 0"/>
      <geometry>
        <mesh filename="package://xm_description/meshes/link_wheel_3.STL"/>
      </geometry>
      <material name="Blue"/>
    </visual>
    <collision>
      <origin rpy="0 0 0" xyz="0 0 0"/>
      <geometry>
        <mesh filename="package://xm_description/meshes/link_wheel_3.stl"/>
      </geometry>
    </collision>
  </link>
  <!-- Attach the arm -->
  <joint name="joint_lift" type="prismatic">
    <origin rpy="-2.7756E-17 0 -1.5708" xyz="-0.04456 0.00022708 0.72985"/>
    <parent link="base_link"/>
    <child link="link_lift"/>
    <axis xyz="0 0 -1"/>
    <limit effort="500" lower="-0.15" upper="0.15" velocity="1"/>
  </joint>
  <link name="link_lift">
    <visual>
      <origin rpy="0 0 0" xyz="0 0 0"/>
      <geometry>
        <mesh filename="package://xm_description/meshes/link_lift.STL"/>
      </geometry>
      <material name="Grey"/>
    </visual>
    <collision>
      <origin rpy="0 0 0" xyz="0 0 0"/>
      <geometry>
        <mesh filename="package://xm_description/meshes/link_lift.stl"/>
      </geometry>
    </collision>
  </link>
  <joint name="joint_waist" type="revolute">
    <origin rpy="2.7756E-17 1.3056E-31 -2.8372E-16" xyz="0 0.0945 0.00415"/>
    <parent link="link_lift"/>
    <child link="link_waist"/>
    <axis xyz="0 0 1"/>
    <limit effort="500" lower="-1.047" upper="1.047" velocity="1"/>
  </joint>
  <link name="link_waist">
    <visual>
      <origin rpy="0 0 0" xyz="0 0 0"/>
      <geometry>
        <mesh filename="package://xm_description/meshes/link_waist.STL"/>
      </geometry>
      <material name="Grey"/>
    </visual>
    <collision>
      <origin rpy="0 0 0" xyz="0 0 0"/>
      <geometry>
        <mesh filename="package://xm_description/meshes/link_waist.stl"/>
      </geometry>
    </collision>
  </link>
  <joint name="joint_big_arm" type="revolute">
    <origin rpy="1.5708 -7.7037E-34 1.5708" xyz="0 0.15678 -0.018"/>
    <parent link="link_waist"/>
    <child link="link_big_arm"/>
    <axis xyz="0 0 1"/>
    <limit effort="500" lower="-1.920" upper="1.396" velocity="1"/>
  </joint>
  <link name="link_big_arm">
    <visual>
      <origin rpy="0 0 0" xyz="0 0 0"/>
      <geometry>
        <mesh filename="package://xm_description/meshes/link_big_arm.STL"/>
      </geometry>
      <material name="Grey"/>
    </visual>
    <collision>
      <origin rpy="0 0 0" xyz="0 0 0"/>
      <geometry>
        <mesh filename="package://xm_description/meshes/link_big_arm.stl"/>
      </geometry>
    </collision>
  </link>
  <joint name="joint_forearm" type="revolute">
    <origin rpy="-6.4095E-31 2.2204E-16 -7.7037E-34" xyz="0.35 0 0"/>
    <parent link="link_big_arm"/>
    <child link="link_forearm"/>
    <axis xyz="0 0 -1"/>
    <limit effort="500" lower="-2.234" upper="2.234" velocity="1"/>
  </joint>
  <link name="link_forearm">
    <visual>
      <origin rpy="0 0 0" xyz="0 0 0"/>
      <geometry>
        <mesh filename="package://xm_description/meshes/link_forearm.STL"/>
      </geometry>
      <material name="Grey"/>
    </visual>
    <collision>
      <origin rpy="0 0 0" xyz="0 0 0"/>
      <geometry>
        <mesh filename="package://xm_description/meshes/link_forearm.stl"/>
      </geometry>
    </collision>
  </link>
  <joint name="joint_wrist_pitching" type="revolute">
    <origin rpy="0 0 1.5708" xyz="0.3 0 0"/>
    <parent link="link_forearm"/>
    <child link="link_wrist_pitching"/>
    <axis xyz="0 0 -1"/>
    <limit effort="500" lower="-2.182" upper="2.182" velocity="1"/>
  </joint>
  <link name="link_wrist_pitching">
    <visual>
      <origin rpy="0 0 0" xyz="0 0 0"/>
      <geometry>
        <mesh filename="package://xm_description/meshes/link_wrist_pitching.STL"/>
      </geometry>
      <material name="Grey"/>
    </visual>
    <collision>
      <origin rpy="0 0 0" xyz="0 0 0"/>
      <geometry>
        <mesh filename="package://xm_description/meshes/link_wrist_pitching.stl"/>
      </geometry>
    </collision>
  </link>
  <joint name="joint_wrist_rotation" type="continuous">
    <origin rpy="1.5708 -1.5708 0" xyz="0 0 0"/>
    <parent link="link_wrist_pitching"/>
    <child link="link_wrist_rotation"/>
    <axis xyz="0 0 1"/>
    <limit effort="500" velocity="1"/>
  </joint>
  <link name="link_wrist_rotation">
    <visual>
      <origin rpy="0 0 0" xyz="0 0 0"/>
      <geometry>
        <mesh filename="package://xm_description/meshes/link_wrist_rotation.STL"/>
      </geometry>
      <material name="Grey"/>
    </visual>
    <collision>
      <origin rpy="0 0 0" xyz="0 0 0"/>
      <geometry>
        <mesh filename="package://xm_description/meshes/link_wrist_rotation.stl"/>
      </geometry>
    </collision>
  </link>
  <!-- Attach the gripper -->
  <joint name="joint_finger_left" type="fixed">
    <origin rpy="1.5708 -1.5708 0" xyz="-0.01295 -0.00014458 0.091042"/>
    <parent link="link_wrist_rotation"/>
    <child link="link_finger_left"/>
    <axis xyz="0 0 -1"/>
    <limit effort="500" lower="-1.571" upper="0" velocity="1"/>
  </joint>
  <link name="link_finger_left">
    <visual>
      <origin rpy="0 0 0" xyz="0 0 0"/>
      <geometry>
        <mesh filename="package://xm_description/meshes/link_finger_left.STL"/>
      </geometry>
      <material name="Green"/>
    </visual>
    <collision>
      <origin rpy="0 0 0" xyz="0 0 0"/>
      <geometry>
        <mesh filename="package://xm_description/meshes/link_finger_left.stl"/>
      </geometry>
    </collision>
  </link>
  <joint name="joint_finger_right" type="fixed">
    <origin rpy="1.5708 -1.5708 0" xyz="0.01295 -0.00014458 0.091042"/>
    <parent link="link_wrist_rotation"/>
    <child link="link_finger_right"/>
    <axis xyz="0 0 -1"/>
    <limit effort="500" lower="0" upper="1.571" velocity="1"/>
  </joint>
  <link name="link_finger_right">
    <visual>
      <origin rpy="0 0 0" xyz="0 0 0"/>
      <geometry>
        <mesh filename="package://xm_description/meshes/link_finger_right.STL"/>
      </geometry>
      <material name="Green"/>
    </visual>
    <collision>
      <origin rpy="0 0 0" xyz="0 0 0"/>
      <geometry>
        <mesh filename="package://xm_description/meshes/link_finger_right.stl"/>
      </geometry>
    </collision>
  </link>
  <!-- Attach the camera -->
  <joint name="joint_camera" type="fixed">
    <origin rpy="5.7785E-17 0 0" xyz="-0.001 0.032 0"/>
    <parent link="link_kinect"/>
    <child link="link_camera"/>
    <axis xyz="0 0 0"/>
  </joint>
  <link name="link_camera">
    <visual>
      <origin rpy="0 0 0" xyz="0 0 0"/>
      <geometry>
        <mesh filename="package://xm_description/meshes/link_camera.STL"/>
      </geometry>
      <material name="Black"/>
    </visual>
    <collision>
      <origin rpy="0 0 0" xyz="0 0 0"/>
      <geometry>
        <mesh filename="package://xm_description/meshes/link_camera.stl"/>
      </geometry>
    </collision>
  </link>
  <!-- Attach the kinect -->
  <joint name="joint_kinect" type="fixed">
    <origin rpy="1.5708 0 -6.1679E-17" xyz="-0.06656 0.00022708 1.1145"/>
    <parent link="base_link"/>
    <child link="link_kinect"/>
    <axis xyz="0 0 1"/>
    <limit effort="500" lower="-0.523" upper="0.523" velocity="1"/>
  </joint>
  <link name="link_kinect">
    <visual>
      <origin rpy="0 0 0" xyz="0 0 0"/>
      <geometry>
        <mesh filename="package://xm_description/meshes/link_kinect.STL"/>
      </geometry>
      <material name="Black"/>
    </visual>
    <collision>
      <origin rpy="0 0 0" xyz="0 0 0"/>
      <geometry>
        <mesh filename="package://xm_description/meshes/link_kinect.stl"/>
      </geometry>
    </collision>
  </link>
  <!-- Attach the laser -->
  <joint name="joint_laser" type="fixed">
    <origin rpy="-6.7054E-18 6.9389E-17 -1.5708" xyz="0.20674 0.00022708 0.181"/>
    <parent link="base_link"/>
    <child link="link_laser"/>
    <axis xyz="0 0 0"/>
  </joint>
  <link name="link_laser">
    <visual>
      <origin rpy="0 0 0" xyz="0 0 0"/>
      <geometry>
        <mesh filename="package://xm_description/meshes/link_laser.STL"/>
      </geometry>
      <material name="Black"/>
    </visual>
    <collision>
      <origin rpy="0 0 0" xyz="0 0 0"/>
      <geometry>
        <mesh filename="package://xm_description/meshes/link_laser.stl"/>
      </geometry>
    </collision>
  </link>
</robot>

